<sdf version='1.6'>
  <world name='default'>
    <light name='sun' type='directional'>
      <cast_shadows>1</cast_shadows>
      <pose frame=''>0 0 10 0 -0 0</pose>
      <diffuse>0.8 0.8 0.8 1</diffuse>
      <specular>0.2 0.2 0.2 1</specular>
      <attenuation>
        <range>1000</range>
        <constant>0.9</constant>
        <linear>0.01</linear>
        <quadratic>0.001</quadratic>
      </attenuation>
      <direction>-0.5 0.1 -0.9</direction>
    </light>
    <model name='ground_plane'>
      <static>1</static>
      <link name='link'>
        <collision name='collision'>
          <geometry>
            <plane>
              <normal>0 0 1</normal>
              <size>100 100</size>
            </plane>
          </geometry>
          <surface>
            <friction>
              <ode>
                <mu>100</mu>
                <mu2>50</mu2>
              </ode>
              <torsional>
                <ode/>
              </torsional>
            </friction>
            <contact>
              <ode/>
            </contact>
            <bounce/>
          </surface>
          <max_contacts>10</max_contacts>
        </collision>
        <visual name='visual'>
          <cast_shadows>0</cast_shadows>
          <geometry>
            <plane>
              <normal>0 0 1</normal>
              <size>100 100</size>
            </plane>
          </geometry>
          <material>
            <script>
              <uri>file://media/materials/scripts/gazebo.material</uri>
              <name>Gazebo/Grey</name>
            </script>
          </material>
        </visual>
        <self_collide>0</self_collide>
        <kinematic>0</kinematic>
      </link>
    </model>
    <gravity>0 0 -9.8</gravity>
    <magnetic_field>6e-06 2.3e-05 -4.2e-05</magnetic_field>
    <atmosphere type='adiabatic'/>
    <physics name='default_physics' default='0' type='ode'>
      <max_step_size>0.001</max_step_size>
      <real_time_factor>1</real_time_factor>
      <real_time_update_rate>1000</real_time_update_rate>
    </physics>
    <scene>
      <ambient>0.4 0.4 0.4 1</ambient>
      <background>0.7 0.7 0.7 1</background>
      <shadows>1</shadows>
    </scene>
    <spherical_coordinates>
      <surface_model>EARTH_WGS84</surface_model>
      <latitude_deg>0</latitude_deg>
      <longitude_deg>0</longitude_deg>
      <elevation>0</elevation>
      <heading_deg>0</heading_deg>
    </spherical_coordinates>
    <model name='youbot'>
      <pose frame=''>0.123509 0.001 0.09 0 -0 0</pose>
      <link name='base_footprint'>
        <pose frame=''>0 0 0 0 -0 0</pose>
        <inertial>
          <pose frame=''>0 0 -0.05 0 -0 0</pose>
          <inertia>
            <ixx>1</ixx>
            <ixy>0</ixy>
            <ixz>0</ixz>
            <iyy>1</iyy>
            <iyz>0</iyz>
            <izz>1</izz>
          </inertia>
          <mass>0.1</mass>
        </inertial>
        <collision name='base_footprint_geom'>
          <pose frame=''>0 0 -0.05 0 -0 0</pose>
          <geometry>
            <box>
              <size>0.001 0.001 0.001</size>
            </box>
          </geometry>
          <surface>
            <friction>
              <ode>
                <mu>0</mu>
                <mu2>0</mu2>
                <fdir1>0 0 0</fdir1>
                <slip1>0</slip1>
                <slip2>0</slip2>
              </ode>
              <torsional>
                <ode/>
              </torsional>
            </friction>
            <bounce>
              <restitution_coefficient>0</restitution_coefficient>
              <threshold>0</threshold>
            </bounce>
            <contact>
              <ode>
                <soft_cfm>0</soft_cfm>
                <soft_erp>0.2</soft_erp>
                <kp>1e+13</kp>
                <kd>1e+11</kd>
                <max_vel>-1</max_vel>
                <min_depth>0</min_depth>
              </ode>
            </contact>
          </surface>
          <laser_retro>0</laser_retro>
          <max_contacts>10</max_contacts>
        </collision>
        <visual name='base_footprint_geom_visual'>
          <pose frame=''>0 0 0 0 -0 0</pose>
          <geometry>
            <box>
              <size>0.001 0.001 0.001</size>
            </box>
          </geometry>
        </visual>
        <gravity>1</gravity>
        <self_collide>0</self_collide>
        <kinematic>0</kinematic>
      </link>
      <link name='base_link'>
        <pose frame=''>0 0 0 0 -0 0</pose>
        <inertial>
          <pose frame=''>0 0 0 0 -0 0</pose>
          <inertia>
            <ixx>5.65223</ixx>
            <ixy>-0.00972</ixy>
            <ixz>1.29399</ixz>
            <iyy>5.66947</iyy>
            <iyz>-0.00738</iyz>
            <izz>3.6832</izz>
          </inertia>
          <mass>22</mass>
        </inertial>
        <collision name='base_link_geom'>
          <pose frame=''>0 0 0 0 -0 0</pose>
          <geometry>
            <mesh>
              <uri>model://youbot/meshes/base/base_convex.stl</uri>
              <scale>1 1 1</scale>
            </mesh>
          </geometry>
          <surface>
            <friction>
              <ode>
                <mu>0</mu>
                <mu2>0</mu2>
                <fdir1>0 0 0</fdir1>
                <slip1>0</slip1>
                <slip2>0</slip2>
              </ode>
              <torsional>
                <ode/>
              </torsional>
            </friction>
            <bounce>
              <restitution_coefficient>0</restitution_coefficient>
              <threshold>0</threshold>
            </bounce>
            <contact>
              <ode>
                <soft_cfm>0</soft_cfm>
                <soft_erp>0.2</soft_erp>
                <kp>1e+13</kp>
                <kd>1e+11</kd>
                <max_vel>-1</max_vel>
                <min_depth>0</min_depth>
              </ode>
            </contact>
          </surface>
          <laser_retro>0</laser_retro>
          <max_contacts>10</max_contacts>
        </collision>
        <visual name='base_link_geom_visual'>
          <pose frame=''>0 0 0 0 -0 0</pose>
          <geometry>
            <mesh>
              <uri>model://youbot/meshes/base/base.dae</uri>
              <scale>1 1 1</scale>
            </mesh>
          </geometry>
        </visual>
        <gravity>1</gravity>
        <self_collide>0</self_collide>
        <kinematic>0</kinematic>
      </link>
      <link name='arm_link_0'>
        <pose frame=''>0.143 0 0.046 0 -0 0</pose>
        <inertial>
          <pose frame=''>0 0 0 0 -0 0</pose>
          <inertia>
            <ixx>0.01</ixx>
            <ixy>0</ixy>
            <ixz>0</ixz>
            <iyy>0.01</iyy>
            <iyz>0</iyz>
            <izz>0.01</izz>
          </inertia>
          <mass>0.845</mass>
        </inertial>
        <collision name='arm_link_0_geom'>
          <pose frame=''>0 0 0 0 -0 0</pose>
          <geometry>
            <mesh>
              <uri>model://youbot/meshes/arm/arm0_convex.stl</uri>
              <scale>1 1 1</scale>
            </mesh>
          </geometry>
          <surface>
            <friction>
              <ode>
                <mu>0</mu>
                <mu2>0</mu2>
                <fdir1>0 0 0</fdir1>
                <slip1>0</slip1>
                <slip2>0</slip2>
              </ode>
              <torsional>
                <ode/>
              </torsional>
            </friction>
            <bounce>
              <restitution_coefficient>0</restitution_coefficient>
              <threshold>0</threshold>
            </bounce>
            <contact>
              <ode>
                <soft_cfm>0</soft_cfm>
                <soft_erp>0.2</soft_erp>
                <kp>1e+13</kp>
                <kd>1e+11</kd>
                <max_vel>-1</max_vel>
                <min_depth>0</min_depth>
              </ode>
            </contact>
          </surface>
          <laser_retro>0</laser_retro>
          <max_contacts>10</max_contacts>
        </collision>
        <visual name='arm_link_0_geom_visual'>
          <pose frame=''>0 0 0 0 -0 0</pose>
          <geometry>
            <mesh>
              <uri>model://youbot/meshes/arm/arm0.dae</uri>
              <scale>1 1 1</scale>
            </mesh>
          </geometry>
          <material>
            <script>
              <uri>model://youbot/materials/scripts/youbot.material</uri>
              <name>youbot/DarkGrey</name>
            </script>
          </material>
        </visual>
        <gravity>1</gravity>
        <self_collide>0</self_collide>
        <kinematic>0</kinematic>
      </link>
      <link name='arm_link_1'>
        <pose frame=''>0.167 0 0.142 0 -0 2.96706</pose>
        <inertial>
          <pose frame=''>0.01489 0.00213 0.00213 0 -0 0</pose>
          <inertia>
            <ixx>0.003863</ixx>
            <ixy>-0.000979</ixy>
            <ixz>0</ixz>
            <iyy>0.006196</iyy>
            <iyz>0</iyz>
            <izz>0.006369</izz>
          </inertia>
          <mass>2.412</mass>
        </inertial>
        <collision name='arm_link_1_geom'>
          <pose frame=''>0 0 0 0 -0 0</pose>
          <geometry>
            <mesh>
              <uri>model://youbot/meshes/arm/arm1_convex.stl</uri>
              <scale>1 1 1</scale>
            </mesh>
          </geometry>
          <surface>
            <friction>
              <ode>
                <mu>0</mu>
                <mu2>0</mu2>
                <fdir1>0 0 0</fdir1>
                <slip1>0</slip1>
                <slip2>0</slip2>
              </ode>
              <torsional>
                <ode/>
              </torsional>
            </friction>
            <bounce>
              <restitution_coefficient>0</restitution_coefficient>
              <threshold>0</threshold>
            </bounce>
            <contact>
              <ode>
                <soft_cfm>0</soft_cfm>
                <soft_erp>0.2</soft_erp>
                <kp>1e+13</kp>
                <kd>1e+11</kd>
                <max_vel>-1</max_vel>
                <min_depth>0</min_depth>
              </ode>
            </contact>
          </surface>
          <laser_retro>0</laser_retro>
          <max_contacts>10</max_contacts>
        </collision>
        <visual name='arm_link_1_geom_visual'>
          <pose frame=''>0 0 0 0 -0 0</pose>
          <geometry>
            <mesh>
              <uri>model://youbot/meshes/arm/arm1.dae</uri>
              <scale>1 1 1</scale>
            </mesh>
          </geometry>
        </visual>
        <gravity>1</gravity>
        <self_collide>0</self_collide>
        <kinematic>0</kinematic>
      </link>
      <link name='arm_link_2'>
        <pose frame=''>0.134501 0.00573 0.161 0 -1.13446 2.96706</pose>
        <inertial>
          <pose frame=''>0.10453 0.0017 -0.00297 0 -0 0</pose>
          <inertia>
            <ixx>0.000823</ixx>
            <ixy>0</ixy>
            <ixz>-0</ixz>
            <iyy>0.004447</iyy>
            <iyz>0</iyz>
            <izz>0.004439</izz>
          </inertia>
          <mass>1.155</mass>
        </inertial>
        <collision name='arm_link_2_geom'>
          <pose frame=''>0 -0.032 0.078 0 -0 0</pose>
          <geometry>
            <mesh>
              <uri>model://youbot/meshes/arm/arm2_convex.stl</uri>
              <scale>1 1 1</scale>
            </mesh>
          </geometry>
          <surface>
            <friction>
              <ode>
                <mu>0</mu>
                <mu2>0</mu2>
                <fdir1>0 0 0</fdir1>
                <slip1>0</slip1>
                <slip2>0</slip2>
              </ode>
              <torsional>
                <ode/>
              </torsional>
            </friction>
            <bounce>
              <restitution_coefficient>0</restitution_coefficient>
              <threshold>0</threshold>
            </bounce>
            <contact>
              <ode>
                <soft_cfm>0</soft_cfm>
                <soft_erp>0.2</soft_erp>
                <kp>1e+13</kp>
                <kd>1e+11</kd>
                <max_vel>-1</max_vel>
                <min_depth>0</min_depth>
              </ode>
            </contact>
          </surface>
          <laser_retro>0</laser_retro>
          <max_contacts>10</max_contacts>
        </collision>
        <visual name='arm_link_2_geom_visual'>
          <pose frame=''>0 -0.032 0.078 0 -0 0</pose>
          <geometry>
            <mesh>
              <uri>model://youbot/meshes/arm/arm2.dae</uri>
              <scale>1 1 1</scale>
            </mesh>
          </geometry>
        </visual>
        <gravity>1</gravity>
        <self_collide>0</self_collide>
        <kinematic>0</kinematic>
      </link>
      <link name='arm_link_3'>
        <pose frame=''>0.272845 -0.018663 0.226506 -0 1.41372 2.96706</pose>
        <inertial>
          <pose frame=''>0.0001 0.0967 0.02107 0 -0 0</pose>
          <inertia>
            <ixx>0.002459</ixx>
            <ixy>0</ixy>
            <ixz>0</ixz>
            <iyy>0.002571</iyy>
            <iyz>-0</iyz>
            <izz>0.000535</izz>
          </inertia>
          <mass>0.934</mass>
        </inertial>
        <collision name='arm_link_3_geom'>
          <pose frame=''>0 0.028 0.079 0 -0 0</pose>
          <geometry>
            <mesh>
              <uri>model://youbot/meshes/arm/arm3_convex.stl</uri>
              <scale>1 1 1</scale>
            </mesh>
          </geometry>
          <surface>
            <friction>
              <ode>
                <mu>0</mu>
                <mu2>0</mu2>
                <fdir1>0 0 0</fdir1>
                <slip1>0</slip1>
                <slip2>0</slip2>
              </ode>
              <torsional>
                <ode/>
              </torsional>
            </friction>
            <bounce>
              <restitution_coefficient>0</restitution_coefficient>
              <threshold>0</threshold>
            </bounce>
            <contact>
              <ode>
                <soft_cfm>0</soft_cfm>
                <soft_erp>0.2</soft_erp>
                <kp>1e+13</kp>
                <kd>1e+11</kd>
                <max_vel>-1</max_vel>
                <min_depth>0</min_depth>
              </ode>
            </contact>
          </surface>
          <laser_retro>0</laser_retro>
          <max_contacts>10</max_contacts>
        </collision>
        <visual name='arm_link_3_geom_visual'>
          <pose frame=''>0 0.028 0.079 0 -0 0</pose>
          <geometry>
            <mesh>
              <uri>model://youbot/meshes/arm/arm3.dae</uri>
              <scale>1 1 1</scale>
            </mesh>
          </geometry>
        </visual>
        <gravity>1</gravity>
        <self_collide>0</self_collide>
        <kinematic>0</kinematic>
      </link>
      <link name='arm_link_4'>
        <pose frame=''>0.141533 0.004491 0.247624 0 -0.375246 2.96706</pose>
        <inertial>
          <pose frame=''>0.00011 0.05103 -0.02319 0 -0 0</pose>
          <inertia>
            <ixx>0.000869</ixx>
            <ixy>0</ixy>
            <ixz>-0</ixz>
            <iyy>0.001173</iyy>
            <iyz>-0.000231</iyz>
            <izz>0.001091</izz>
          </inertia>
          <mass>0.877</mass>
        </inertial>
        <collision name='arm_link_4_geom'>
          <pose frame=''>0 -0.01 0.029 0 -0 0</pose>
          <geometry>
            <mesh>
              <uri>model://youbot/meshes/arm/arm4_convex.stl</uri>
              <scale>1 1 1</scale>
            </mesh>
          </geometry>
          <surface>
            <friction>
              <ode>
                <mu>0</mu>
                <mu2>0</mu2>
                <fdir1>0 0 0</fdir1>
                <slip1>0</slip1>
                <slip2>0</slip2>
              </ode>
              <torsional>
                <ode/>
              </torsional>
            </friction>
            <bounce>
              <restitution_coefficient>0</restitution_coefficient>
              <threshold>0</threshold>
            </bounce>
            <contact>
              <ode>
                <soft_cfm>0</soft_cfm>
                <soft_erp>0.2</soft_erp>
                <kp>1e+13</kp>
                <kd>1e+11</kd>
                <max_vel>-1</max_vel>
                <min_depth>0</min_depth>
              </ode>
            </contact>
          </surface>
          <laser_retro>0</laser_retro>
          <max_contacts>10</max_contacts>
        </collision>
        <visual name='arm_link_4_geom_visual'>
          <pose frame=''>0 -0.01 0.029 0 -0 0</pose>
          <geometry>
            <mesh>
              <uri>model://youbot/meshes/arm/arm4.dae</uri>
              <scale>1 1 1</scale>
            </mesh>
          </geometry>
        </visual>
        <gravity>1</gravity>
        <self_collide>0</self_collide>
        <kinematic>0</kinematic>
      </link>
      <link name='arm_link_5'>
        <pose frame=''>0.190287 -0.004106 0.367846 -0.085052 0.365926 -0.408445</pose>
        <inertial>
          <pose frame=''>0 0.00115 -0.01683 0 -0 0</pose>
          <inertia>
            <ixx>0.00028</ixx>
            <ixy>0</ixy>
            <ixz>0</ixz>
            <iyy>0.000339</iyy>
            <iyz>0</iyz>
            <izz>0.000119</izz>
          </inertia>
          <mass>0.251</mass>
        </inertial>
        <collision name='arm_link_5_geom'>
          <pose frame=''>0.003 0 -0.034 0 -0 0</pose>
          <geometry>
            <mesh>
              <uri>model://youbot/meshes/arm/arm5_convex.stl</uri>
              <scale>1 1 1</scale>
            </mesh>
          </geometry>
          <surface>
            <bounce>
              <restitution_coefficient>0</restitution_coefficient>
              <threshold>0</threshold>
            </bounce>
            <contact>
              <ode>
                <soft_cfm>0</soft_cfm>
                <soft_erp>0.2</soft_erp>
                <kp>1e+13</kp>
                <kd>1e+11</kd>
                <max_vel>-1</max_vel>
                <min_depth>0</min_depth>
              </ode>
            </contact>
            <friction>
              <torsional>
                <ode/>
              </torsional>
              <ode/>
            </friction>
          </surface>
          <laser_retro>0</laser_retro>
          <max_contacts>10</max_contacts>
        </collision>
        <visual name='arm_link_5_geom_visual'>
          <pose frame=''>0.003 0 -0.034 0 -0 0</pose>
          <geometry>
            <mesh>
              <uri>model://youbot/meshes/arm/arm5.dae</uri>
              <scale>1 1 1</scale>
            </mesh>
          </geometry>
        </visual>
        <gravity>1</gravity>
        <self_collide>0</self_collide>
        <kinematic>0</kinematic>
      </link>
      <link name='gripper_palm_link'>
        <pose frame=''>0.190287 -0.004106 0.367846 -0.085052 0.365926 -0.408445</pose>
        <inertial>
          <pose frame=''>0 0 0 0 -0 0</pose>
          <inertia>
            <ixx>0.01</ixx>
            <ixy>0</ixy>
            <ixz>0</ixz>
            <iyy>0.01</iyy>
            <iyz>0</iyz>
            <izz>0.01</izz>
          </inertia>
          <mass>0.1</mass>
        </inertial>
        <collision name='gripper_palm_link_geom'>
          <pose frame=''>0 0 0 0 -0 0</pose>
          <geometry>
            <mesh>
              <uri>model://youbot/meshes/gripper/palm_convex.stl</uri>
              <scale>1 1 1</scale>
            </mesh>
          </geometry>
          <surface>
            <friction>
              <ode>
                <mu>0</mu>
                <mu2>0</mu2>
                <fdir1>0 0 0</fdir1>
                <slip1>0</slip1>
                <slip2>0</slip2>
              </ode>
              <torsional>
                <ode/>
              </torsional>
            </friction>
            <bounce>
              <restitution_coefficient>0</restitution_coefficient>
              <threshold>0</threshold>
            </bounce>
            <contact>
              <ode>
                <soft_cfm>0</soft_cfm>
                <soft_erp>0.2</soft_erp>
                <kp>1e+13</kp>
                <kd>1e+11</kd>
                <max_vel>-1</max_vel>
                <min_depth>0</min_depth>
              </ode>
            </contact>
          </surface>
          <laser_retro>0</laser_retro>
          <max_contacts>10</max_contacts>
        </collision>
        <visual name='gripper_palm_link_geom_visual'>
          <pose frame=''>0 0 0 0 -0 0</pose>
          <geometry>
            <mesh>
              <uri>model://youbot/meshes/gripper/palm.stl</uri>
              <scale>1 1 1</scale>
            </mesh>
          </geometry>
          <material>
            <script>
              <uri>file://media/materials/scripts/gazebo.material</uri>
              <name>Gazebo/Black</name>
            </script>
          </material>
        </visual>
        <gravity>1</gravity>
        <self_collide>1</self_collide>
        <kinematic>0</kinematic>
      </link>
      <link name='gripper_finger_link_l'>
        <pose frame=''>0.21326 -0.001105 0.408579 0.085052 -0.365926 2.73315</pose>
        <inertial>
          <pose frame=''>0 -0.001 0 0 -0 0</pose>
          <inertia>
            <ixx>0.01</ixx>
            <ixy>0</ixy>
            <ixz>0</ixz>
            <iyy>0.01</iyy>
            <iyz>0</iyz>
            <izz>0.01</izz>
          </inertia>
          <mass>0.01</mass>
        </inertial>
        <collision name='gripper_finger_link_l_geom'>
          <pose frame=''>0 0 0 0 -0 0</pose>
          <geometry>
            <mesh>
              <uri>model://youbot/meshes/gripper/finger_convex.stl</uri>
              <scale>1 1 1</scale>
            </mesh>
          </geometry>
          <surface>
            <bounce>
              <restitution_coefficient>0</restitution_coefficient>
              <threshold>0</threshold>
            </bounce>
            <contact>
              <ode>
                <soft_cfm>100</soft_cfm>
                <soft_erp>0.2</soft_erp>
                <kp>1e+13</kp>
                <kd>1e+11</kd>
                <max_vel>10</max_vel>
                <min_depth>10</min_depth>
              </ode>
            </contact>
            <friction>
              <torsional>
              	<coefficient>1</coefficient>
                <ode/>
              </torsional>
              <ode/>
            </friction>
          </surface>
          <laser_retro>0</laser_retro>
          <max_contacts>10</max_contacts>
        </collision>
        <visual name='gripper_finger_link_l_geom_visual'>
          <pose frame=''>0 0 0 0 -0 0</pose>
          <geometry>
            <mesh>
              <uri>model://youbot/meshes/gripper/finger.stl</uri>
              <scale>1 1 1</scale>
            </mesh>
          </geometry>
        </visual>
        <gravity>1</gravity>
        <self_collide>0</self_collide>
        <kinematic>0</kinematic>
      </link>
      <link name='gripper_finger_link_r'>
        <pose frame=''>0.207375 -0.015929 0.409848 -0.085052 0.365926 -0.408445</pose>
        <inertial>
          <pose frame=''>0 -0.001 0 0 -0 0</pose>
          <inertia>
            <ixx>0.01</ixx>
            <ixy>0</ixy>
            <ixz>0</ixz>
            <iyy>0.01</iyy>
            <iyz>0</iyz>
            <izz>0.01</izz>
          </inertia>
          <mass>0.01</mass>
        </inertial>
        <collision name='gripper_finger_link_r_geom'>
          <pose frame=''>0 0 0 0 -0 0</pose>
          <geometry>
            <mesh>
              <uri>model://youbot/meshes/gripper/finger_convex.stl</uri>
              <scale>1 1 1</scale>
            </mesh>
          </geometry>
          <surface>
            <bounce>
              <restitution_coefficient>0</restitution_coefficient>
              <threshold>0</threshold>
            </bounce>
            <contact>
              <ode>
                <soft_cfm>100</soft_cfm>
                <soft_erp>0.2</soft_erp>
                <kp>1e+13</kp>
                <kd>1e+11</kd>
                <max_vel>10</max_vel>
                <min_depth>10</min_depth>
              </ode>
            </contact>
            <friction>
              <torsional>
              	<coefficient>1</coefficient>
                <ode/>
              </torsional>
              <ode/>
            </friction>
          </surface>
          <laser_retro>0</laser_retro>
          <max_contacts>10</max_contacts>
        </collision>
        <visual name='gripper_finger_link_r_geom_visual'>
          <pose frame=''>0 0 0 0 -0 0</pose>
          <geometry>
            <mesh>
              <uri>model://youbot/meshes/gripper/finger.stl</uri>
              <scale>1 1 1</scale>
            </mesh>
          </geometry>
        </visual>
        <gravity>1</gravity>
        <self_collide>0</self_collide>
        <kinematic>0</kinematic>
      </link>
      <link name='base_laser_front_link'>
        <pose frame=''>0.3 0 -0.03 0 -0 0</pose>
        <inertial>
          <pose frame=''>0 0 0 0 -0 0</pose>
          <inertia>
            <ixx>0.1</ixx>
            <ixy>0</ixy>
            <ixz>0</ixz>
            <iyy>0.1</iyy>
            <iyz>0</iyz>
            <izz>0.1</izz>
          </inertia>
          <mass>0.16</mass>
        </inertial>
        <collision name='base_laser_front_link_geom'>
          <pose frame=''>0 0 0 0 -0 0</pose>
          <geometry>
            <mesh>
              <uri>model://hokuyo/meshes/hokuyo_convex.stl</uri>
              <scale>1 1 1</scale>
            </mesh>
          </geometry>
          <surface>
            <bounce>
              <restitution_coefficient>0</restitution_coefficient>
              <threshold>0</threshold>
            </bounce>
            <contact>
              <ode>
                <soft_cfm>0</soft_cfm>
                <soft_erp>0.2</soft_erp>
                <kp>1e+13</kp>
                <kd>1e+11</kd>
                <max_vel>-1</max_vel>
                <min_depth>0</min_depth>
              </ode>
            </contact>
            <friction>
              <torsional>
                <ode/>
              </torsional>
              <ode/>
            </friction>
          </surface>
          <laser_retro>0</laser_retro>
          <max_contacts>10</max_contacts>
        </collision>
        <visual name='base_laser_front_link_geom_visual'>
          <pose frame=''>0 0 0 0 -0 0</pose>
          <geometry>
            <mesh>
              <uri>model://hokuyo/meshes/hokuyo.dae</uri>
              <scale>1 1 1</scale>
            </mesh>
          </geometry>
        </visual>
        <sensor name='base_laser_front' type='ray'>
          <pose frame=''>0 0 0 0 -0 0</pose>
          <ray>
            <scan>
              <horizontal>
                <samples>640</samples>
                <resolution>1</resolution>
                <min_angle>-1.57</min_angle>
                <max_angle>1.57</max_angle>
              </horizontal>
              <vertical>
                <samples>5</samples>
                <resolution>1</resolution>
                <min_angle>0</min_angle>
                <max_angle>1.57</max_angle>
              </vertical>
            </scan>
            <range>
              <min>0.05</min>
              <max>1.6</max>
              <resolution>0.36</resolution>
            </range>
          </ray>
          <always_on>0</always_on>
          <update_rate>10</update_rate>
          <visualize>0</visualize>
        </sensor>
        <sensor name='te_veo' type='camera'>
          <pose frame=''>0 0 0.3 0 -0 0</pose>
          <camera name='__default__'>
            <horizontal_fov>1.047</horizontal_fov>
            <image>
              <width>640</width>
              <height>480</height>
              <format>R8G8B8</format>
            </image>
            <clip>
              <near>0.1</near>
              <far>100</far>
            </clip>
          </camera>
          <always_on>1</always_on>
          <update_rate>0.5</update_rate>
          <visualize>0</visualize>
          <plugin name='ojo' filename='libte_veo.so'>
            <topic>camara</topic>
          </plugin>
        </sensor>
        <gravity>1</gravity>
        <self_collide>0</self_collide>
        <kinematic>0</kinematic>
      </link>
      <link name='caster_link_bl'>
        <pose frame=''>-0.228 0.158 -0.034 0 -0 0</pose>
        <inertial>
          <pose frame=''>0 0 0 0 -0 0</pose>
          <inertia>
            <ixx>0.012412</ixx>
            <ixy>-0.000712</ixy>
            <ixz>0.000503</ixz>
            <iyy>0.015218</iyy>
            <iyz>-4e-06</iyz>
            <izz>0.011764</izz>
          </inertia>
          <mass>0.1</mass>
        </inertial>
        <gravity>1</gravity>
        <self_collide>0</self_collide>
        <kinematic>0</kinematic>
      </link>
      <link name='wheel_link_bl'>
        <pose frame=''>-0.228 0.158 -0.034 0 -0 0</pose>
        <inertial>
          <pose frame=''>0 0 0 0 -0 0</pose>
          <inertia>
            <ixx>0.012412</ixx>
            <ixy>-0.000712</ixy>
            <ixz>0.000503</ixz>
            <iyy>0.015218</iyy>
            <iyz>-4e-06</iyz>
            <izz>0.011764</izz>
          </inertia>
          <mass>0.4</mass>
        </inertial>
        <collision name='wheel_link_bl_geom'>
          <pose frame=''>0 0 0 1.5708 -0 0</pose>
          <geometry>
            <cylinder>
              <radius>0.05</radius>
              <length>0.005</length>
            </cylinder>
          </geometry>
          <surface>
            <bounce>
              <restitution_coefficient>0</restitution_coefficient>
              <threshold>0</threshold>
            </bounce>
            <contact>
              <ode>
                <soft_cfm>0</soft_cfm>
                <soft_erp>0.2</soft_erp>
                <kp>1e+13</kp>
                <kd>1e+11</kd>
                <max_vel>-1</max_vel>
                <min_depth>0</min_depth>
              </ode>
            </contact>
            <friction>
              <torsional>
                <ode/>
              </torsional>
              <ode/>
            </friction>
          </surface>
          <laser_retro>0</laser_retro>
          <max_contacts>10</max_contacts>
        </collision>
        <visual name='wheel_link_bl_geom_visual'>
          <pose frame=''>0 0 0 0 -0 0</pose>
          <geometry>
            <mesh>
              <uri>model://youbot/meshes/base/back-left_wheel.dae</uri>
              <scale>1 1 1</scale>
            </mesh>
          </geometry>
          <material>
            <script>
              <uri>model://youbot/materials/scripts/youbot.material</uri>
              <name>youbot/Orange</name>
            </script>
          </material>
        </visual>
        <gravity>1</gravity>
        <self_collide>0</self_collide>
        <kinematic>0</kinematic>
      </link>
      <link name='caster_link_br'>
        <pose frame=''>-0.228 -0.158 -0.034 0 -0 0</pose>
        <inertial>
          <pose frame=''>0 0 0 0 -0 0</pose>
          <inertia>
            <ixx>0.012412</ixx>
            <ixy>-0.000712</ixy>
            <ixz>0.000503</ixz>
            <iyy>0.015218</iyy>
            <iyz>-4e-06</iyz>
            <izz>0.011764</izz>
          </inertia>
          <mass>0.1</mass>
        </inertial>
        <gravity>1</gravity>
        <self_collide>0</self_collide>
        <kinematic>0</kinematic>
      </link>
      <link name='wheel_link_br'>
        <pose frame=''>-0.228 -0.158 -0.034 0 -0 0</pose>
        <inertial>
          <pose frame=''>0 0 0 0 -0 0</pose>
          <inertia>
            <ixx>0.012412</ixx>
            <ixy>-0.000712</ixy>
            <ixz>0.000503</ixz>
            <iyy>0.015218</iyy>
            <iyz>-4e-06</iyz>
            <izz>0.011764</izz>
          </inertia>
          <mass>0.4</mass>
        </inertial>
        <collision name='wheel_link_br_geom'>
          <pose frame=''>0 0 0 1.5708 -0 0</pose>
          <geometry>
            <cylinder>
              <radius>0.05</radius>
              <length>0.005</length>
            </cylinder>
          </geometry>
          <surface>
            <bounce>
              <restitution_coefficient>0</restitution_coefficient>
              <threshold>0</threshold>
            </bounce>
            <contact>
              <ode>
                <soft_cfm>0</soft_cfm>
                <soft_erp>0.2</soft_erp>
                <kp>1e+13</kp>
                <kd>1e+11</kd>
                <max_vel>-1</max_vel>
                <min_depth>0</min_depth>
              </ode>
            </contact>
            <friction>
              <torsional>
                <ode/>
              </torsional>
              <ode/>
            </friction>
          </surface>
          <laser_retro>0</laser_retro>
          <max_contacts>10</max_contacts>
        </collision>
        <visual name='wheel_link_br_geom_visual'>
          <pose frame=''>0 0 0 0 -0 0</pose>
          <geometry>
            <mesh>
              <uri>model://youbot/meshes/base/back-right_wheel.dae</uri>
              <scale>1 1 1</scale>
            </mesh>
          </geometry>
          <material>
            <script>
              <uri>model://youbot/materials/scripts/youbot.material</uri>
              <name>youbot/Orange</name>
            </script>
          </material>
        </visual>
        <gravity>1</gravity>
        <self_collide>0</self_collide>
        <kinematic>0</kinematic>
      </link>
      <link name='caster_link_fl'>
        <pose frame=''>0.228 0.158 -0.034 0 -0 0</pose>
        <inertial>
          <pose frame=''>0 0 0 0 -0 0</pose>
          <inertia>
            <ixx>0.012412</ixx>
            <ixy>-0.000712</ixy>
            <ixz>0.000503</ixz>
            <iyy>0.015218</iyy>
            <iyz>-4e-06</iyz>
            <izz>0.011764</izz>
          </inertia>
          <mass>0.1</mass>
        </inertial>
        <gravity>1</gravity>
        <self_collide>0</self_collide>
        <kinematic>0</kinematic>
      </link>
      <link name='wheel_link_fl'>
        <pose frame=''>0.228 0.158 -0.034 0 -0 0</pose>
        <inertial>
          <pose frame=''>0 0 0 0 -0 0</pose>
          <inertia>
            <ixx>0.012412</ixx>
            <ixy>-0.000712</ixy>
            <ixz>0.000503</ixz>
            <iyy>0.015218</iyy>
            <iyz>-4e-06</iyz>
            <izz>0.011764</izz>
          </inertia>
          <mass>0.4</mass>
        </inertial>
        <collision name='wheel_link_fl_geom'>
          <pose frame=''>0 0 0 1.5708 -0 0</pose>
          <geometry>
            <cylinder>
              <radius>0.05</radius>
              <length>0.005</length>
            </cylinder>
          </geometry>
          <surface>
            <bounce>
              <restitution_coefficient>0</restitution_coefficient>
              <threshold>0</threshold>
            </bounce>
            <contact>
              <ode>
                <soft_cfm>0</soft_cfm>
                <soft_erp>0.2</soft_erp>
                <kp>1e+13</kp>
                <kd>1e+11</kd>
                <max_vel>-1</max_vel>
                <min_depth>0</min_depth>
              </ode>
            </contact>
            <friction>
              <torsional>
                <ode/>
              </torsional>
              <ode/>
            </friction>
          </surface>
          <laser_retro>0</laser_retro>
          <max_contacts>10</max_contacts>
        </collision>
        <visual name='wheel_link_fl_geom_visual'>
          <pose frame=''>0 0 0 0 -0 0</pose>
          <geometry>
            <mesh>
              <uri>model://youbot/meshes/base/front-left_wheel.dae</uri>
              <scale>1 1 1</scale>
            </mesh>
          </geometry>
          <material>
            <script>
              <uri>model://youbot/materials/scripts/youbot.material</uri>
              <name>youbot/Orange</name>
            </script>
          </material>
        </visual>
        <gravity>1</gravity>
        <self_collide>0</self_collide>
        <kinematic>0</kinematic>
      </link>
      <link name='caster_link_fr'>
        <pose frame=''>0.228 -0.158 -0.034 0 -0 0</pose>
        <inertial>
          <pose frame=''>0 0 0 0 -0 0</pose>
          <inertia>
            <ixx>0.012412</ixx>
            <ixy>-0.000712</ixy>
            <ixz>0.000503</ixz>
            <iyy>0.015218</iyy>
            <iyz>-4e-06</iyz>
            <izz>0.011764</izz>
          </inertia>
          <mass>0.1</mass>
        </inertial>
        <gravity>1</gravity>
        <self_collide>0</self_collide>
        <kinematic>0</kinematic>
      </link>
      <link name='wheel_link_fr'>
        <pose frame=''>0.228 -0.158 -0.034 0 -0 0</pose>
        <inertial>
          <pose frame=''>0 0 0 0 -0 0</pose>
          <inertia>
            <ixx>0.012412</ixx>
            <ixy>-0.000712</ixy>
            <ixz>0.000503</ixz>
            <iyy>0.015218</iyy>
            <iyz>-4e-06</iyz>
            <izz>0.011764</izz>
          </inertia>
          <mass>0.4</mass>
        </inertial>
        <collision name='wheel_link_fr_geom'>
          <pose frame=''>0 0 0 1.5708 -0 0</pose>
          <geometry>
            <cylinder>
              <radius>0.05</radius>
              <length>0.005</length>
            </cylinder>
          </geometry>
          <surface>
            <bounce>
              <restitution_coefficient>0</restitution_coefficient>
              <threshold>0</threshold>
            </bounce>
            <contact>
              <ode>
                <soft_cfm>0</soft_cfm>
                <soft_erp>0.2</soft_erp>
                <kp>1e+13</kp>
                <kd>1e+11</kd>
                <max_vel>-1</max_vel>
                <min_depth>0</min_depth>
              </ode>
            </contact>
            <friction>
              <torsional>
                <ode/>
              </torsional>
              <ode/>
            </friction>
          </surface>
          <laser_retro>0</laser_retro>
          <max_contacts>10</max_contacts>
        </collision>
        <visual name='wheel_link_fr_geom_visual'>
          <pose frame=''>0 0 0 0 -0 0</pose>
          <geometry>
            <mesh>
              <uri>model://youbot/meshes/base/front-right_wheel.dae</uri>
              <scale>1 1 1</scale>
            </mesh>
          </geometry>
          <material>
            <script>
              <uri>model://youbot/materials/scripts/youbot.material</uri>
              <name>youbot/Orange</name>
            </script>
          </material>
        </visual>
        <gravity>1</gravity>
        <self_collide>0</self_collide>
        <kinematic>0</kinematic>
      </link>
      <link name='plate_link'>
        <pose frame=''>-0.159 0 0.046 0 -0 0</pose>
        <inertial>
          <pose frame=''>0 0 0 0 -0 0</pose>
          <inertia>
            <ixx>0.01</ixx>
            <ixy>0</ixy>
            <ixz>0</ixz>
            <iyy>0.01</iyy>
            <iyz>0</iyz>
            <izz>0.01</izz>
          </inertia>
          <mass>1</mass>
        </inertial>
        <collision name='plate_link_geom'>
          <pose frame=''>0 0 0 0 -0 0</pose>
          <geometry>
            <mesh>
              <uri>model://youbot/meshes/plate/plate_convex.stl</uri>
              <scale>1 1 1</scale>
            </mesh>
          </geometry>
          <surface>
            <bounce>
              <restitution_coefficient>0</restitution_coefficient>
              <threshold>0</threshold>
            </bounce>
            <contact>
              <ode>
                <soft_cfm>0</soft_cfm>
                <soft_erp>0.2</soft_erp>
                <kp>1e+13</kp>
                <kd>1e+11</kd>
                <max_vel>-1</max_vel>
                <min_depth>0</min_depth>
              </ode>
            </contact>
            <friction>
              <torsional>
                <ode/>
              </torsional>
              <ode/>
            </friction>
          </surface>
          <laser_retro>0</laser_retro>
          <max_contacts>10</max_contacts>
        </collision>
        <visual name='plate_link_geom_visual'>
          <pose frame=''>0 0 0 0 -0 0</pose>
          <geometry>
            <mesh>
              <uri>model://youbot/meshes/plate/plate.dae</uri>
              <scale>1 1 1</scale>
            </mesh>
          </geometry>
        </visual>
        <gravity>1</gravity>
        <self_collide>0</self_collide>
        <kinematic>0</kinematic>
      </link>
      <joint name='base_footprint_joint' type='revolute'>
        <pose frame=''>0 0 0 0 -0 0</pose>
        <parent>base_footprint</parent>
        <child>base_link</child>
        <axis>
          <dynamics>
            <damping>0</damping>
            <friction>0</friction>
            <spring_reference>0</spring_reference>
            <spring_stiffness>0</spring_stiffness>
          </dynamics>
          <limit>
            <lower>0</lower>
            <upper>0</upper>
            <effort>0</effort>
            <velocity>0</velocity>
          </limit>
          <xyz>0 0 1</xyz>
          <use_parent_model_frame>1</use_parent_model_frame>
        </axis>
      </joint>
      <joint name='arm_joint_0' type='revolute'>
        <pose frame=''>0 0 0 0 -0 0</pose>
        <parent>base_link</parent>
        <child>arm_link_0</child>
        <axis>
          <dynamics>
            <damping>0</damping>
            <friction>0</friction>
            <spring_reference>0</spring_reference>
            <spring_stiffness>0</spring_stiffness>
          </dynamics>
          <limit>
            <lower>0</lower>
            <upper>0</upper>
            <effort>0</effort>
            <velocity>0</velocity>
          </limit>
          <xyz>0 0 1</xyz>
          <use_parent_model_frame>1</use_parent_model_frame>
        </axis>
      </joint>
      <joint name='arm_joint_1' type='revolute'>
        <pose frame=''>0 0 0 0 -0 0</pose>
        <parent>arm_link_0</parent>
        <child>arm_link_1</child>
        <axis>
          <dynamics>
            <damping>1</damping>
            <friction>0</friction>
            <spring_reference>0</spring_reference>
            <spring_stiffness>0</spring_stiffness>
          </dynamics>
          <limit>
            <lower>0</lower>
            <upper>5.89921</upper>
            <effort>9.5</effort>
          </limit>
          <xyz>0 0 -1</xyz>
          <use_parent_model_frame>1</use_parent_model_frame>
        </axis>
      </joint>
      <joint name='arm_joint_2' type='revolute'>
        <pose frame=''>0 0 0 0 -0 0</pose>
        <parent>arm_link_1</parent>
        <child>arm_link_2</child>
        <axis>
          <dynamics>
            <damping>1</damping>
            <friction>0</friction>
            <spring_reference>0</spring_reference>
            <spring_stiffness>0</spring_stiffness>
          </dynamics>
          <limit>
            <lower>0</lower>
            <upper>2.70526</upper>
            <effort>9.5</effort>
            <velocity>-1</velocity>
          </limit>
          <xyz>-0.173648 -0.984808 0</xyz>
          <use_parent_model_frame>1</use_parent_model_frame>
        </axis>
      </joint>
      <joint name='arm_joint_3' type='revolute'>
        <pose frame=''>0 0 0 0 -0 0</pose>
        <parent>arm_link_2</parent>
        <child>arm_link_3</child>
        <axis>
          <dynamics>
            <damping>1</damping>
            <friction>0</friction>
            <spring_reference>0</spring_reference>
            <spring_stiffness>0</spring_stiffness>
          </dynamics>
          <limit>
            <lower>-5.18363</lower>
            <upper>0</upper>
            <effort>6</effort>
            <velocity>-1</velocity>
          </limit>
          <xyz>-0.173648 -0.984808 0</xyz>
          <use_parent_model_frame>1</use_parent_model_frame>
        </axis>
      </joint>
      <joint name='arm_joint_4' type='revolute'>
        <pose frame=''>0 0 0 0 -0 0</pose>
        <parent>arm_link_3</parent>
        <child>arm_link_4</child>
        <axis>
          <dynamics>
            <damping>1</damping>
            <friction>0</friction>
            <spring_reference>0</spring_reference>
            <spring_stiffness>0</spring_stiffness>
          </dynamics>
          <limit>
            <lower>0</lower>
            <upper>3.57793</upper>
            <effort>2</effort>
            <velocity>-1</velocity>
          </limit>
          <xyz>-0.173648 -0.984808 0</xyz>
          <use_parent_model_frame>1</use_parent_model_frame>
        </axis>
      </joint>
      <joint name='arm_joint_5' type='revolute'>
        <pose frame=''>0 0 0 0 -0 0</pose>
        <parent>arm_link_4</parent>
        <child>arm_link_5</child>
        <axis>
          <dynamics>
            <damping>1</damping>
            <friction>0</friction>
            <spring_reference>0</spring_reference>
            <spring_stiffness>0</spring_stiffness>
          </dynamics>
          <limit>
            <lower>-0.2</lower>
            <upper>5.84685</upper>
            <effort>1</effort>
            <velocity>-1</velocity>
          </limit>
          <xyz>-0.360933 0.063642 -0.930418</xyz>
          <use_parent_model_frame>1</use_parent_model_frame>
        </axis>
      </joint>
      <joint name='gripper_palm_joint' type='revolute'>
        <pose frame=''>0 0 0 0 -0 0</pose>
        <parent>arm_link_5</parent>
        <child>gripper_palm_link</child>
        <axis>
          <dynamics>
            <damping>0</damping>
            <friction>0</friction>
            <spring_reference>0</spring_reference>
            <spring_stiffness>0</spring_stiffness>
          </dynamics>
          <limit>
            <lower>0</lower>
            <upper>0</upper>
            <effort>0</effort>
            <velocity>0</velocity>
          </limit>
          <xyz>0 0 1</xyz>
          <use_parent_model_frame>1</use_parent_model_frame>
        </axis>
      </joint>
      <joint name='gripper_finger_joint_l' type='prismatic'>
        <pose frame=''>0 0 0 0 -0 0</pose>
        <parent>gripper_palm_link</parent>
        <child>gripper_finger_link_l</child>
        <axis>
          <dynamics>
            <damping>1</damping>
            <friction>0</friction>
            <spring_reference>0</spring_reference>
            <spring_stiffness>0</spring_stiffness>
          </dynamics>
          <limit>
            <lower>0</lower>
            <upper>0.0115</upper>
            <effort>1</effort>
            <velocity>-1</velocity>
          </limit>
          <xyz>0.367852 0.926495 -0.079325</xyz>
          <use_parent_model_frame>1</use_parent_model_frame>
        </axis>
      </joint>
      <joint name='gripper_finger_joint_r' type='prismatic'>
        <pose frame=''>0 0 0 0 -0 0</pose>
        <parent>gripper_palm_link</parent>
        <child>gripper_finger_link_r</child>
        <axis>
          <dynamics>
            <damping>1</damping>
            <friction>0</friction>
            <spring_reference>0</spring_reference>
            <spring_stiffness>0</spring_stiffness>
          </dynamics>
          <limit>
            <lower>0</lower>
            <upper>0.0115</upper>
            <effort>1</effort>
            <velocity>-1</velocity>
          </limit>
          <xyz>-0.367852 -0.926495 0.079325</xyz>
          <use_parent_model_frame>1</use_parent_model_frame>
        </axis>
      </joint>
      <joint name='base_laser_front_hokuyo_urg04_laser_joint' type='revolute'>
        <pose frame=''>0 0 0 0 -0 0</pose>
        <parent>base_link</parent>
        <child>base_laser_front_link</child>
        <axis>
          <dynamics>
            <damping>0</damping>
            <friction>0</friction>
            <spring_reference>0</spring_reference>
            <spring_stiffness>0</spring_stiffness>
          </dynamics>
          <limit>
            <lower>0</lower>
            <upper>0</upper>
            <effort>0</effort>
            <velocity>0</velocity>
          </limit>
          <xyz>0 0 1</xyz>
          <use_parent_model_frame>1</use_parent_model_frame>
        </axis>
      </joint>
      <joint name='caster_joint_bl' type='revolute'>
        <pose frame=''>0 0 0 0 -0 0</pose>
        <parent>base_link</parent>
        <child>caster_link_bl</child>
        <axis>
          <dynamics>
            <damping>1</damping>
            <friction>0</friction>
            <spring_reference>0</spring_reference>
            <spring_stiffness>0</spring_stiffness>
          </dynamics>
          <limit>
            <effort>1</effort>
            <lower>-1e+16</lower>
            <upper>1e+16</upper>
          </limit>
          <xyz>0 0 1</xyz>
          <use_parent_model_frame>1</use_parent_model_frame>
        </axis>
      </joint>
      <joint name='wheel_joint_bl' type='revolute'>
        <pose frame=''>0 0 0 0 -0 0</pose>
        <parent>caster_link_bl</parent>
        <child>wheel_link_bl</child>
        <axis>
          <dynamics>
            <damping>1</damping>
            <friction>0</friction>
            <spring_reference>0</spring_reference>
            <spring_stiffness>0</spring_stiffness>
          </dynamics>
          <limit>
            <effort>1</effort>
            <lower>-1e+16</lower>
            <upper>1e+16</upper>
          </limit>
          <xyz>0 1 0</xyz>
          <use_parent_model_frame>1</use_parent_model_frame>
        </axis>
      </joint>
      <joint name='caster_joint_br' type='revolute'>
        <pose frame=''>0 0 0 0 -0 0</pose>
        <parent>base_link</parent>
        <child>caster_link_br</child>
        <axis>
          <dynamics>
            <damping>1</damping>
            <friction>0</friction>
            <spring_reference>0</spring_reference>
            <spring_stiffness>0</spring_stiffness>
          </dynamics>
          <limit>
            <effort>1</effort>
            <lower>-1e+16</lower>
            <upper>1e+16</upper>
          </limit>
          <xyz>0 0 1</xyz>
          <use_parent_model_frame>1</use_parent_model_frame>
        </axis>
      </joint>
      <joint name='wheel_joint_br' type='revolute'>
        <pose frame=''>0 0 0 0 -0 0</pose>
        <parent>caster_link_br</parent>
        <child>wheel_link_br</child>
        <axis>
          <dynamics>
            <damping>1</damping>
            <friction>0</friction>
            <spring_reference>0</spring_reference>
            <spring_stiffness>0</spring_stiffness>
          </dynamics>
          <limit>
            <effort>1</effort>
            <lower>-1e+16</lower>
            <upper>1e+16</upper>
          </limit>
          <xyz>0 1 0</xyz>
          <use_parent_model_frame>1</use_parent_model_frame>
        </axis>
      </joint>
      <joint name='caster_joint_fl' type='revolute'>
        <pose frame=''>0 0 0 0 -0 0</pose>
        <parent>base_link</parent>
        <child>caster_link_fl</child>
        <axis>
          <dynamics>
            <damping>1</damping>
            <friction>0</friction>
            <spring_reference>0</spring_reference>
            <spring_stiffness>0</spring_stiffness>
          </dynamics>
          <limit>
            <effort>1</effort>
            <lower>-1e+16</lower>
            <upper>1e+16</upper>
          </limit>
          <xyz>0 0 1</xyz>
          <use_parent_model_frame>1</use_parent_model_frame>
        </axis>
      </joint>
      <joint name='wheel_joint_fl' type='revolute'>
        <pose frame=''>0 0 0 0 -0 0</pose>
        <parent>caster_link_fl</parent>
        <child>wheel_link_fl</child>
        <axis>
          <dynamics>
            <damping>1</damping>
            <friction>0</friction>
            <spring_reference>0</spring_reference>
            <spring_stiffness>0</spring_stiffness>
          </dynamics>
          <limit>
            <effort>1</effort>
            <lower>-1e+16</lower>
            <upper>1e+16</upper>
          </limit>
          <xyz>0 1 0</xyz>
          <use_parent_model_frame>1</use_parent_model_frame>
        </axis>
      </joint>
      <joint name='caster_joint_fr' type='revolute'>
        <pose frame=''>0 0 0 0 -0 0</pose>
        <parent>base_link</parent>
        <child>caster_link_fr</child>
        <axis>
          <dynamics>
            <damping>1</damping>
            <friction>0</friction>
            <spring_reference>0</spring_reference>
            <spring_stiffness>0</spring_stiffness>
          </dynamics>
          <limit>
            <effort>1</effort>
            <lower>-1e+16</lower>
            <upper>1e+16</upper>
          </limit>
          <xyz>0 0 1</xyz>
          <use_parent_model_frame>1</use_parent_model_frame>
        </axis>
      </joint>
      <joint name='wheel_joint_fr' type='revolute'>
        <pose frame=''>0 0 0 0 -0 0</pose>
        <parent>caster_link_fr</parent>
        <child>wheel_link_fr</child>
        <axis>
          <dynamics>
            <damping>1</damping>
            <friction>0</friction>
            <spring_reference>0</spring_reference>
            <spring_stiffness>0</spring_stiffness>
          </dynamics>
          <limit>
            <effort>1</effort>
            <lower>-1e+16</lower>
            <upper>1e+16</upper>
          </limit>
          <xyz>0 1 0</xyz>
          <use_parent_model_frame>1</use_parent_model_frame>
        </axis>
      </joint>
      <joint name='plate_joint' type='revolute'>
        <parent>base_link</parent>
        <child>plate_link</child>
        <axis>
          <dynamics>
            <damping>0</damping>
            <friction>0</friction>
            <spring_reference>0</spring_reference>
            <spring_stiffness>0</spring_stiffness>
          </dynamics>
          <limit>
            <lower>0</lower>
            <upper>0</upper>
            <effort>0</effort>
            <velocity>0</velocity>
          </limit>
          <xyz>0 0 1</xyz>
          <use_parent_model_frame>1</use_parent_model_frame>
        </axis>
      </joint>
      <static>0</static>
      <plugin name='actuador' filename='libmi_robot.so'>
        <topic>robotito</topic>
      </plugin>
    </model>
    <state world_name='default'>
      <sim_time>0 0</sim_time>
      <real_time>0 0</real_time>
      <!--  <wall_time>1520879028 450675210</wall_time>-->
      <wall_time>0 0</wall_time>
      <iterations>0</iterations>
      <model name='ground_plane'>
        <pose frame=''>0 0 0 0 -0 0</pose>
        <scale>1 1 1</scale>
        <link name='link'>
          <pose frame=''>0 0 0 0 -0 0</pose>
          <velocity>0 0 0 0 -0 0</velocity>
          <acceleration>0 0 0 0 -0 0</acceleration>
          <wrench>0 0 0 0 -0 0</wrench>
        </link>
      </model>
      
      <!-- <model name='youbot'>
        <pose frame=''>0.121487 0.01 0.083974 7e-06 2e-05 0.000374</pose>
        <scale>1 1 1</scale>
        <link name='arm_link_0'>
          <pose frame=''>0.264487 -0.1019 0.129969 1.2e-05 2.2e-05 0.000374</pose>
          <velocity>4.4e-05 -0.000424 0.000603 0.003614 0.000959 -0.001466</velocity>
          <acceleration>0.010432 -0.122147 -0.045623 0.967899 -0.232269 -0.825259</acceleration>
          <wrench>0.008815 -0.103214 -0.038552 0 -0 0</wrench>
        </link>
        <link name='arm_link_1'>
          <pose frame=''>0.288489 -0.101891 0.225968 -2.2e-05 -2.9e-05 2.96592</pose>
          <velocity>0.000142 -0.000706 0.000563 0.005443 0.000921 -0.001376</velocity>
          <acceleration>-0.006572 -0.129191 -0.059842 3.01287 -0.441225 -0.735307</acceleration>
          <wrench>-0.015852 -0.311608 -0.14434 0 -0 0</wrench>
        </link>
        <link name='arm_link_2'>
          <pose frame=''>0.255997 -0.096124 0.244968 -8.8e-05 -1.1345 2.96597</pose>
          <velocity>0.000157 -0.000767 0.000514 0.007159 0.000922 -0.006069</velocity>
          <acceleration>-0.006987 -0.335969 -0.142468 1.0787 -1.15695 1.79006</acceleration>
          <wrench>-0.00807 -0.388045 -0.16455 0 -0 0</wrench>
        </link>
        <link name='arm_link_3'>
          <pose frame=''>0.394316 -0.120678 0.310452 0.000466 1.41376 2.96636</pose>
          <velocity>0.000202 -0.001413 -0.001509 0.0035 0.026183 -0.005405</velocity>
          <acceleration>-0.391288 -0.374662 -1.09674 -2.22339 1.06959 -2.19909</acceleration>
          <wrench>-0.365463 -0.349934 -1.02435 0 -0 0</wrench>
        </link>
        <link name='arm_link_4'>
          <pose frame=''>0.263032 -0.09737 0.331562 0.000108 -0.375269 2.96586</pose>
          <velocity>0.000912 -0.000835 0.001341 -0.00293 0.002541 -0.005712</velocity>
          <acceleration>0.358832 -0.032221 0.974423 -1.88825 -0.844253 -2.57933</acceleration>
          <wrench>0.314695 -0.028257 0.854569 0 -0 0</wrench>
        </link>
        <link name='arm_link_5'>
          <pose frame=''>0.311779 -0.106014 0.451783 -0.101295 0.361963 -0.454977</pose>
          <velocity>0.00113 -0.000344 0.001063 0.005837 0.000146 -0.004395</velocity>
          <acceleration>0.739584 0.910993 0.482363 3.04704 -1.29044 -1.90762</acceleration>
          <wrench>0.185636 0.228659 0.121073 0 -0 0</wrench>
        </link>
        <link name='base_footprint'>
          <pose frame=''>0.121487 -0.101953 0.083974 7e-06 2e-05 0.000374</pose>
          <velocity>3e-06 -0.000215 0.000804 0.002666 0.00103 -0.000449</velocity>
          <acceleration>0.031809 -0.125852 -0.013576 0.022459 -0.158579 0.192143</acceleration>
          <wrench>0.003181 -0.012585 -0.001358 0 -0 0</wrench>
        </link>
        <link name='base_laser_front_link'>
          <pose frame=''>0.421486 -0.101841 0.053968 7e-06 2e-05 0.000374</pose>
          <velocity>-2.7e-05 -0.000268 0.000498 0.002662 0.001028 -0.000428</velocity>
          <acceleration>0.029278 -0.066645 0.036844 0.018868 -0.160322 0.213077</acceleration>
          <wrench>0.004684 -0.010663 0.005895 0 -0 0</wrench>
        </link>
        <link name='base_link'>
          <pose frame=''>0.121487 -0.101953 0.083974 7e-06 2e-05 0.000374</pose>
          <velocity>3e-06 -0.000215 0.000807 0.002667 0.001032 -0.000449</velocity>
          <acceleration>0.023995 -0.126885 -0.010605 0.023777 -0.157269 0.192646</acceleration>
          <wrench>0.527885 -2.79146 -0.233304 0 -0 0</wrench>
        </link>
        <link name='caster_link_bl'>
          <pose frame=''>-0.106573 0.055961 0.049999 7e-06 2e-05 -0.001674</pose>
          <velocity>5.9e-05 -8.3e-05 0.000159 0.002617 0.001028 -0.000631</velocity>
          <acceleration>0.019727 -0.230773 -1.34742 -0.026396 -0.160315 0.010804</acceleration>
          <wrench>0.001973 -0.023077 -0.134742 0 -0 0</wrench>
        </link>
        <link name='caster_link_br'>
          <pose frame=''>-0.106455 -0.260038 0.049998 7e-06 2e-05 -0.001455</pose>
          <velocity>-6.7e-05 -8.4e-05 0.000298 0.002636 0.001035 -0.000709</velocity>
          <acceleration>0.096269 -0.231911 -0.372635 -0.007166 -0.153529 -0.066957</acceleration>
          <wrench>0.009627 -0.023191 -0.037263 0 -0 0</wrench>
        </link>
        <link name='caster_link_fl'>
          <pose frame=''>0.349427 0.056132 0.049999 7e-06 2e-05 -0.0008</pose>
          <velocity>5.9e-05 -0.00017 0.000382 0.002679 0.001037 -0.000633</velocity>
          <acceleration>0.01945 -0.024702 -0.58288 0.035278 -0.15187 0.0084</acceleration>
          <wrench>0.001945 -0.00247 -0.058288 0 -0 0</wrench>
        </link>
        <link name='caster_link_fr'>
          <pose frame=''>0.349545 -0.259867 0.049995 7e-06 2e-05 -0.000618</pose>
          <velocity>-5.6e-05 -0.000172 0.000508 0.002699 0.001034 -0.000697</velocity>
          <acceleration>0.10689 -0.027092 0.378917 0.055801 -0.155125 -0.055312</acceleration>
          <wrench>0.010689 -0.002709 0.037892 0 -0 0</wrench>
        </link>
        <link name='gripper_finger_link_l'>
          <pose frame=''>0.339637 -0.092868 0.491321 0.101296 -0.361965 2.68662</pose>
          <velocity>0.000488 -0.002256 0.0013 0.005133 0.001571 -0.002147</velocity>
          <acceleration>2.892 1.02024 10.1163 1.82887 -1.43804 2.27471</acceleration>
          <wrench>0.02892 0.010202 0.101163 0 -0 0</wrench>
        </link>
        <link name='gripper_finger_link_r'>
          <pose frame=''>0.3285 -0.117877 0.493921 -0.101296 0.361965 -0.454977</pose>
          <velocity>0.000441 -0.002246 0.001196 0.005036 0.001606 -0.002108</velocity>
          <acceleration>2.84167 1.03095 10.0038 1.65235 -1.39186 2.34616</acceleration>
          <wrench>0.028417 0.010309 0.100038 0 -0 0</wrench>
        </link>
        <link name='gripper_palm_link'>
          <pose frame=''>0.311779 -0.106013 0.451783 -0.101296 0.361965 -0.454977</pose>
          <velocity>0.001204 -0.000162 0.001073 0.005178 0.001555 -0.002166</velocity>
          <acceleration>0.78912 1.02197 0.492116 2.53178 0.363787 -1.52478</acceleration>
          <wrench>0.078912 0.102197 0.049212 0 -0 0</wrench>
        </link>
        <link name='plate_link'>
          <pose frame=''>-0.037513 -0.102013 0.129977 7e-06 2e-05 0.000374</pose>
          <velocity>5e-05 -0.000266 0.000982 0.002671 0.001036 -0.000448</velocity>
          <acceleration>0.016703 -0.157623 -0.024624 0.02713 -0.153107 0.19405</acceleration>
          <wrench>0.016703 -0.157623 -0.024624 0 -0 0</wrench>
        </link>
        <link name='wheel_link_bl'>
          <pose frame=''>-0.106573 0.055961 0.049998 6e-06 -0.045045 -0.001674</pose>
          <velocity>7.1e-05 -0.000123 0.000222 0.002513 0.001459 -0.000627</velocity>
          <acceleration>0.031609 -0.270453 -1.28404 -0.130949 0.270081 0.01586</acceleration>
          <wrench>0.012644 -0.108181 -0.513614 0 -0 0</wrench>
        </link>
        <link name='wheel_link_br'>
          <pose frame=''>-0.106455 -0.260038 0.049997 7e-06 -0.037198 -0.001455</pose>
          <velocity>-4.5e-05 -0.000125 0.00031 0.002536 -0.000851 -0.000706</velocity>
          <acceleration>0.117968 -0.272804 -0.361341 3.03491 -1.10221 3.0726</acceleration>
          <wrench>0.047187 -0.109121 -0.144537 0 -0 0</wrench>
        </link>
        <link name='wheel_link_fl'>
          <pose frame=''>0.349427 0.056132 0.049998 7e-06 -0.017087 -0.000801</pose>
          <velocity>7.1e-05 -0.000136 0.000412 0.002742 0.001462 -0.000638</velocity>
          <acceleration>0.031605 0.008585 -0.552739 0.098531 0.273126 0.003962</acceleration>
          <wrench>0.012642 0.003434 -0.221095 0 -0 0</wrench>
        </link>
        <link name='wheel_link_fr'>
          <pose frame=''>0.349545 -0.259867 0.049994 8e-06 -0.012739 -0.000618</pose>
          <velocity>-2.7e-05 -0.00014 0.000482 0.00277 -0.000488 -0.000705</velocity>
          <acceleration>0.136109 0.005318 0.352345 -3.01406 -1.46472 3.07723</acceleration>
          <wrench>0.054444 0.002127 0.140938 0 -0 0</wrench>
        </link>
      </model>-->
      <light name='sun'>
        <pose frame=''>0 0 10 0 -0 0</pose>
        <cast_shadows>1</cast_shadows>
      </light>
    </state>
    <gui fullscreen='0'>
      <camera name='user_camera'>
        <pose frame=''>0.553856 -2.927752 1.103004 0 0.495641 1.452992</pose>
        <view_controller>orbit</view_controller>
        <projection_type>perspective</projection_type>
      </camera>
    </gui>
    <model name='cinta_transportadora'>
      <pose frame=''>0.786561 0 0.1 0 -0 0</pose>
      <static>true</static>
      <link name='link'>
        <collision name='collision'>
          <geometry>
            <box>
              <size>0.5 3 0.2</size>
            </box>
          </geometry>
          <max_contacts>10</max_contacts>
          <surface>
			<friction>
				<ode>
					<mu>10</mu>
					<mu2>10</mu2>
				</ode>
			</friction>
          </surface>
        </collision>
        <visual name='visual'>
          <geometry>
            <box>
              <size>0.5 3 0.2</size>
            </box>
          </geometry>
          <material>
            <!-- <script>
              <name>Gazebo/Black</name>
              <uri>file://media/materials/scripts/gazebo.material</uri>
            </script>-->
            <diffuse>0 1 0 1</diffuse>
          </material>
        </visual>
        <self_collide>1</self_collide>
        <kinematic>0</kinematic>
      </link>
    </model>
    
    <model name='pieza'>
      <pose frame=''>0.77 -0.015 0.20 0 -0 0</pose>

      <link name='tronco'>
      	<pose frame=''>0 0 0.0255 0 -0 0</pose>
      	<inertial>
          	<mass>0.010</mass>
          	<inertia>
          		<!-- https://en.wikipedia.org/wiki/List_of_moments_of_inertia -->
	          	<ixx>2.2708e-06</ixx> <!-- 1/12*masa*(z*z+y*y) -->
				<ixy>0.0</ixy>         
				<ixz>0.0</ixz>         
				<iyy>2.2708e-06</iyy> <!-- 1/12*masa*(z*z+x*x) -->        
				<iyz>0.0</iyz>         
				<izz>3.75e-07</izz> <!-- 1/12*masa*(x*x+y*y) -->  
	        </inertia>
        </inertial>
        <self_collide>0</self_collide>
	    <kinematic>0</kinematic>
	    <gravity>1</gravity>
        <collision name='collision'>
          <geometry>
            <!--  <cylinder>
              <radius>0.005</radius>
              <length>0.1</length>
            </cylinder>-->
            <box>
            	<size>0.015 0.015 0.05</size>
            </box>
          </geometry>
          <max_contacts>10</max_contacts>
          <surface>
            <contact>
				<ode>
					<soft_cfm>0.2</soft_cfm>
					<soft_erp>0.2</soft_erp>
					<kp>1e5</kp>
					<kd>1.0</kd>
				</ode>
			</contact>
			<friction>
				<ode>
					<mu>1e1</mu>
					<mu2>1e1</mu2>
					<fdir1>1.000000 1.000000 1.000000</fdir1>
				</ode>
			</friction>
			<contact>
				<ode>
					<max_vel>0.1</max_vel>
					<min_depth>0.001</min_depth>
				</ode>
			</contact>
        
          </surface>
        </collision>
        <visual name='visual'>
          <geometry>
            <!--  <cylinder>
              <radius>0.005</radius>
              <length>0.1</length>
            </cylinder>-->
            <box>
            	<size>0.015 0.015 0.05</size>
            </box>
          </geometry>
          <material>
            <script>
              <name>Gazebo/Red</name>
              <uri>file://media/materials/scripts/gazebo.material</uri>
            </script>
          </material>
        </visual>
      </link>

    </model>
    
    
    
  </world>
</sdf>
